Internal Server Error: /api/register/
Traceback (most recent call last):
  File "/home/mario/Documentos/Webs/Idea Millonaria/Back/env/lib/python3.13/site-packages/django/core/handlers/exception.py", line 55, in inner
    response = get_response(request)
  File "/home/mario/Documentos/Webs/Idea Millonaria/Back/env/lib/python3.13/site-packages/django/core/handlers/base.py", line 197, in _get_response
    response = wrapped_callback(request, *callback_args, **callback_kwargs)
  File "/home/mario/Documentos/Webs/Idea Millonaria/Back/env/lib/python3.13/site-packages/django/views/decorators/csrf.py", line 65, in _view_wrapper
    return view_func(request, *args, **kwargs)
  File "/home/mario/Documentos/Webs/Idea Millonaria/Back/env/lib/python3.13/site-packages/django/views/generic/base.py", line 104, in view
    return self.dispatch(request, *args, **kwargs)
           ~~~~~~~~~~~~~^^^^^^^^^^^^^^^^^^^^^^^^^^
  File "/home/mario/Documentos/Webs/Idea Millonaria/Back/env/lib/python3.13/site-packages/rest_framework/views.py", line 509, in dispatch
    response = self.handle_exception(exc)
  File "/home/mario/Documentos/Webs/Idea Millonaria/Back/env/lib/python3.13/site-packages/rest_framework/views.py", line 469, in handle_exception
    self.raise_uncaught_exception(exc)
    ~~~~~~~~~~~~~~~~~~~~~~~~~~~~~^^^^^
  File "/home/mario/Documentos/Webs/Idea Millonaria/Back/env/lib/python3.13/site-packages/rest_framework/views.py", line 480, in raise_uncaught_exception
    raise exc
  File "/home/mario/Documentos/Webs/Idea Millonaria/Back/env/lib/python3.13/site-packages/rest_framework/views.py", line 506, in dispatch
    response = handler(request, *args, **kwargs)
  File "/home/mario/Documentos/Webs/Idea Millonaria/Back/iberomoto/accounts/views.py", line 20, in post
    if User.objects.filter(username=username).exists():
       ^^^^^^^^^^^^
  File "/home/mario/Documentos/Webs/Idea Millonaria/Back/env/lib/python3.13/site-packages/django/db/models/manager.py", line 196, in __get__
    raise AttributeError(
    ...<5 lines>...
    )
AttributeError: Manager isn't available; 'auth.User' has been swapped for 'accounts.CustomUser'
"POST /api/register/ HTTP/1.1" 500 110082
Internal Server Error: /api/register/
Traceback (most recent call last):
  File "/home/mario/Documentos/Webs/Idea Millonaria/Back/env/lib/python3.13/site-packages/django/core/handlers/exception.py", line 55, in inner
    response = get_response(request)
  File "/home/mario/Documentos/Webs/Idea Millonaria/Back/env/lib/python3.13/site-packages/django/core/handlers/base.py", line 197, in _get_response
    response = wrapped_callback(request, *callback_args, **callback_kwargs)
  File "/home/mario/Documentos/Webs/Idea Millonaria/Back/env/lib/python3.13/site-packages/django/views/decorators/csrf.py", line 65, in _view_wrapper
    return view_func(request, *args, **kwargs)
  File "/home/mario/Documentos/Webs/Idea Millonaria/Back/env/lib/python3.13/site-packages/django/views/generic/base.py", line 104, in view
    return self.dispatch(request, *args, **kwargs)
           ~~~~~~~~~~~~~^^^^^^^^^^^^^^^^^^^^^^^^^^
  File "/home/mario/Documentos/Webs/Idea Millonaria/Back/env/lib/python3.13/site-packages/rest_framework/views.py", line 509, in dispatch
    response = self.handle_exception(exc)
  File "/home/mario/Documentos/Webs/Idea Millonaria/Back/env/lib/python3.13/site-packages/rest_framework/views.py", line 469, in handle_exception
    self.raise_uncaught_exception(exc)
    ~~~~~~~~~~~~~~~~~~~~~~~~~~~~~^^^^^
  File "/home/mario/Documentos/Webs/Idea Millonaria/Back/env/lib/python3.13/site-packages/rest_framework/views.py", line 480, in raise_uncaught_exception
    raise exc
  File "/home/mario/Documentos/Webs/Idea Millonaria/Back/env/lib/python3.13/site-packages/rest_framework/views.py", line 506, in dispatch
    response = handler(request, *args, **kwargs)
  File "/home/mario/Documentos/Webs/Idea Millonaria/Back/iberomoto/accounts/views.py", line 20, in post
    if User.objects.filter(username=username).exists():
       ^^^^^^^^^^^^
  File "/home/mario/Documentos/Webs/Idea Millonaria/Back/env/lib/python3.13/site-packages/django/db/models/manager.py", line 196, in __get__
    raise AttributeError(
    ...<5 lines>...
    )
AttributeError: Manager isn't available; 'auth.User' has been swapped for 'accounts.CustomUser'
"POST /api/register/ HTTP/1.1" 500 110088
