Internal Server Error: /api/register/
"POST /api/register/ HTTP/1.1" 500 40
Internal Server Error: /admin/routes/route/add/
Traceback (most recent call last):
  File "/home/mario/Documentos/Webs/Idea Millonaria/IM/env/lib/python3.13/site-packages/django/db/backends/utils.py", line 105, in _execute
    return self.cursor.execute(sql, params)
           ~~~~~~~~~~~~~~~~~~~^^^^^^^^^^^^^
psycopg2.errors.NotNullViolation: el valor nulo en la columna «start_location» de la relación «routes_route» viola la restricción de no nulo
DETAIL:  La fila que falla contiene (1, Mieres-Oviedo, , null, null, 2025-03-10 12:44:51.882392+00, 8, 0102000020E61000000600000084373E2B4E1F17C0F0072D1143A0454052AE27...).


The above exception was the direct cause of the following exception:

Traceback (most recent call last):
  File "/home/mario/Documentos/Webs/Idea Millonaria/IM/env/lib/python3.13/site-packages/django/core/handlers/exception.py", line 55, in inner
    response = get_response(request)
  File "/home/mario/Documentos/Webs/Idea Millonaria/IM/env/lib/python3.13/site-packages/django/core/handlers/base.py", line 197, in _get_response
    response = wrapped_callback(request, *callback_args, **callback_kwargs)
  File "/home/mario/Documentos/Webs/Idea Millonaria/IM/env/lib/python3.13/site-packages/django/contrib/admin/options.py", line 718, in wrapper
    return self.admin_site.admin_view(view)(*args, **kwargs)
           ~~~~~~~~~~~~~~~~~~~~~~~~~~~~~~~~^^^^^^^^^^^^^^^^^
  File "/home/mario/Documentos/Webs/Idea Millonaria/IM/env/lib/python3.13/site-packages/django/utils/decorators.py", line 188, in _view_wrapper
    result = _process_exception(request, e)
  File "/home/mario/Documentos/Webs/Idea Millonaria/IM/env/lib/python3.13/site-packages/django/utils/decorators.py", line 186, in _view_wrapper
    response = view_func(request, *args, **kwargs)
  File "/home/mario/Documentos/Webs/Idea Millonaria/IM/env/lib/python3.13/site-packages/django/views/decorators/cache.py", line 80, in _view_wrapper
    response = view_func(request, *args, **kwargs)
  File "/home/mario/Documentos/Webs/Idea Millonaria/IM/env/lib/python3.13/site-packages/django/contrib/admin/sites.py", line 241, in inner
    return view(request, *args, **kwargs)
  File "/home/mario/Documentos/Webs/Idea Millonaria/IM/env/lib/python3.13/site-packages/django/contrib/admin/options.py", line 1961, in add_view
    return self.changeform_view(request, None, form_url, extra_context)
           ~~~~~~~~~~~~~~~~~~~~^^^^^^^^^^^^^^^^^^^^^^^^^^^^^^^^^^^^^^^^
  File "/home/mario/Documentos/Webs/Idea Millonaria/IM/env/lib/python3.13/site-packages/django/utils/decorators.py", line 48, in _wrapper
    return bound_method(*args, **kwargs)
  File "/home/mario/Documentos/Webs/Idea Millonaria/IM/env/lib/python3.13/site-packages/django/utils/decorators.py", line 188, in _view_wrapper
    result = _process_exception(request, e)
  File "/home/mario/Documentos/Webs/Idea Millonaria/IM/env/lib/python3.13/site-packages/django/utils/decorators.py", line 186, in _view_wrapper
    response = view_func(request, *args, **kwargs)
  File "/home/mario/Documentos/Webs/Idea Millonaria/IM/env/lib/python3.13/site-packages/django/contrib/admin/options.py", line 1820, in changeform_view
    return self._changeform_view(request, object_id, form_url, extra_context)
           ~~~~~~~~~~~~~~~~~~~~~^^^^^^^^^^^^^^^^^^^^^^^^^^^^^^^^^^^^^^^^^^^^^
  File "/home/mario/Documentos/Webs/Idea Millonaria/IM/env/lib/python3.13/site-packages/django/contrib/admin/options.py", line 1871, in _changeform_view
    self.save_model(request, new_object, form, not add)
    ~~~~~~~~~~~~~~~^^^^^^^^^^^^^^^^^^^^^^^^^^^^^^^^^^^^
  File "/home/mario/Documentos/Webs/Idea Millonaria/IM/env/lib/python3.13/site-packages/django/contrib/admin/options.py", line 1294, in save_model
    obj.save()
    ~~~~~~~~^^
  File "/home/mario/Documentos/Webs/Idea Millonaria/IM/env/lib/python3.13/site-packages/django/db/models/base.py", line 892, in save
    self.save_base(
    ~~~~~~~~~~~~~~^
        using=using,
        ^^^^^^^^^^^^
    ...<2 lines>...
        update_fields=update_fields,
        ^^^^^^^^^^^^^^^^^^^^^^^^^^^^
    )
    ^
  File "/home/mario/Documentos/Webs/Idea Millonaria/IM/env/lib/python3.13/site-packages/django/db/models/base.py", line 998, in save_base
    updated = self._save_table(
        raw,
    ...<4 lines>...
        update_fields,
    )
  File "/home/mario/Documentos/Webs/Idea Millonaria/IM/env/lib/python3.13/site-packages/django/db/models/base.py", line 1161, in _save_table
    results = self._do_insert(
        cls._base_manager, using, fields, returning_fields, raw
    )
  File "/home/mario/Documentos/Webs/Idea Millonaria/IM/env/lib/python3.13/site-packages/django/db/models/base.py", line 1202, in _do_insert
    return manager._insert(
           ~~~~~~~~~~~~~~~^
        [self],
        ^^^^^^^
    ...<3 lines>...
        raw=raw,
        ^^^^^^^^
    )
    ^
  File "/home/mario/Documentos/Webs/Idea Millonaria/IM/env/lib/python3.13/site-packages/django/db/models/manager.py", line 87, in manager_method
    return getattr(self.get_queryset(), name)(*args, **kwargs)
           ~~~~~~~~~~~~~~~~~~~~~~~~~~~~~~~~~~^^^^^^^^^^^^^^^^^
  File "/home/mario/Documentos/Webs/Idea Millonaria/IM/env/lib/python3.13/site-packages/django/db/models/query.py", line 1847, in _insert
    return query.get_compiler(using=using).execute_sql(returning_fields)
           ~~~~~~~~~~~~~~~~~~~~~~~~~~~~~~~~~~~~~~~~~~~^^^^^^^^^^^^^^^^^^
  File "/home/mario/Documentos/Webs/Idea Millonaria/IM/env/lib/python3.13/site-packages/django/db/models/sql/compiler.py", line 1836, in execute_sql
    cursor.execute(sql, params)
    ~~~~~~~~~~~~~~^^^^^^^^^^^^^
  File "/home/mario/Documentos/Webs/Idea Millonaria/IM/env/lib/python3.13/site-packages/django/db/backends/utils.py", line 122, in execute
    return super().execute(sql, params)
           ~~~~~~~~~~~~~~~^^^^^^^^^^^^^
  File "/home/mario/Documentos/Webs/Idea Millonaria/IM/env/lib/python3.13/site-packages/django/db/backends/utils.py", line 79, in execute
    return self._execute_with_wrappers(
           ~~~~~~~~~~~~~~~~~~~~~~~~~~~^
        sql, params, many=False, executor=self._execute
        ^^^^^^^^^^^^^^^^^^^^^^^^^^^^^^^^^^^^^^^^^^^^^^^
    )
    ^
  File "/home/mario/Documentos/Webs/Idea Millonaria/IM/env/lib/python3.13/site-packages/django/db/backends/utils.py", line 92, in _execute_with_wrappers
    return executor(sql, params, many, context)
  File "/home/mario/Documentos/Webs/Idea Millonaria/IM/env/lib/python3.13/site-packages/django/db/backends/utils.py", line 100, in _execute
    with self.db.wrap_database_errors:
         ^^^^^^^^^^^^^^^^^^^^^^^^^^^^
  File "/home/mario/Documentos/Webs/Idea Millonaria/IM/env/lib/python3.13/site-packages/django/db/utils.py", line 91, in __exit__
    raise dj_exc_value.with_traceback(traceback) from exc_value
  File "/home/mario/Documentos/Webs/Idea Millonaria/IM/env/lib/python3.13/site-packages/django/db/backends/utils.py", line 105, in _execute
    return self.cursor.execute(sql, params)
           ~~~~~~~~~~~~~~~~~~~^^^^^^^^^^^^^
django.db.utils.IntegrityError: el valor nulo en la columna «start_location» de la relación «routes_route» viola la restricción de no nulo
DETAIL:  La fila que falla contiene (1, Mieres-Oviedo, , null, null, 2025-03-10 12:44:51.882392+00, 8, 0102000020E61000000600000084373E2B4E1F17C0F0072D1143A0454052AE27...).

"POST /admin/routes/route/add/ HTTP/1.1" 500 217968
GEOS_ERROR: ParseException: Unknown WKB type 337

GEOS_ERROR: ParseException: Unknown WKB type 337

GEOS_ERROR: ParseException: Unknown WKB type 337

GEOS_ERROR: ParseException: Unknown WKB type 337

Internal Server Error: /admin/routes/route/
Traceback (most recent call last):
  File "/home/mario/Documentos/Webs/Idea Millonaria/IM/env/lib/python3.13/site-packages/django/core/handlers/exception.py", line 55, in inner
    response = get_response(request)
  File "/home/mario/Documentos/Webs/Idea Millonaria/IM/env/lib/python3.13/site-packages/django/core/handlers/base.py", line 197, in _get_response
    response = wrapped_callback(request, *callback_args, **callback_kwargs)
  File "/home/mario/Documentos/Webs/Idea Millonaria/IM/env/lib/python3.13/site-packages/django/contrib/admin/options.py", line 718, in wrapper
    return self.admin_site.admin_view(view)(*args, **kwargs)
           ~~~~~~~~~~~~~~~~~~~~~~~~~~~~~~~~^^^^^^^^^^^^^^^^^
  File "/home/mario/Documentos/Webs/Idea Millonaria/IM/env/lib/python3.13/site-packages/django/utils/decorators.py", line 188, in _view_wrapper
    result = _process_exception(request, e)
  File "/home/mario/Documentos/Webs/Idea Millonaria/IM/env/lib/python3.13/site-packages/django/utils/decorators.py", line 186, in _view_wrapper
    response = view_func(request, *args, **kwargs)
  File "/home/mario/Documentos/Webs/Idea Millonaria/IM/env/lib/python3.13/site-packages/django/views/decorators/cache.py", line 80, in _view_wrapper
    response = view_func(request, *args, **kwargs)
  File "/home/mario/Documentos/Webs/Idea Millonaria/IM/env/lib/python3.13/site-packages/django/contrib/admin/sites.py", line 241, in inner
    return view(request, *args, **kwargs)
  File "/home/mario/Documentos/Webs/Idea Millonaria/IM/env/lib/python3.13/site-packages/django/utils/decorators.py", line 48, in _wrapper
    return bound_method(*args, **kwargs)
  File "/home/mario/Documentos/Webs/Idea Millonaria/IM/env/lib/python3.13/site-packages/django/utils/decorators.py", line 188, in _view_wrapper
    result = _process_exception(request, e)
  File "/home/mario/Documentos/Webs/Idea Millonaria/IM/env/lib/python3.13/site-packages/django/utils/decorators.py", line 186, in _view_wrapper
    response = view_func(request, *args, **kwargs)
  File "/home/mario/Documentos/Webs/Idea Millonaria/IM/env/lib/python3.13/site-packages/django/contrib/admin/options.py", line 2140, in changelist_view
    "selection_note": _("0 of %(cnt)s selected") % {"cnt": len(cl.result_list)},
                                                           ~~~^^^^^^^^^^^^^^^^
  File "/home/mario/Documentos/Webs/Idea Millonaria/IM/env/lib/python3.13/site-packages/django/db/models/query.py", line 382, in __len__
    self._fetch_all()
    ~~~~~~~~~~~~~~~^^
  File "/home/mario/Documentos/Webs/Idea Millonaria/IM/env/lib/python3.13/site-packages/django/db/models/query.py", line 1928, in _fetch_all
    self._result_cache = list(self._iterable_class(self))
                         ~~~~^^^^^^^^^^^^^^^^^^^^^^^^^^^^
  File "/home/mario/Documentos/Webs/Idea Millonaria/IM/env/lib/python3.13/site-packages/django/db/models/query.py", line 123, in __iter__
    for row in compiler.results_iter(results):
               ~~~~~~~~~~~~~~~~~~~~~^^^^^^^^^
  File "/home/mario/Documentos/Webs/Idea Millonaria/IM/env/lib/python3.13/site-packages/django/db/models/sql/compiler.py", line 1512, in apply_converters
    value = converter(value, expression, connection)
  File "/home/mario/Documentos/Webs/Idea Millonaria/IM/env/lib/python3.13/site-packages/django/contrib/gis/db/backends/postgis/operations.py", line 418, in converter
    return None if value is None else GEOSGeometryBase(read(value), geom_class)
                                                       ~~~~^^^^^^^
  File "/home/mario/Documentos/Webs/Idea Millonaria/IM/env/lib/python3.13/site-packages/django/contrib/gis/geos/prototypes/io.py", line 172, in read
    return wkb_reader_read(self.ptr, wkb_s, len(wkb_s))
  File "/home/mario/Documentos/Webs/Idea Millonaria/IM/env/lib/python3.13/site-packages/django/contrib/gis/geos/libgeos.py", line 154, in __call__
    return self.func(*args)
           ~~~~~~~~~^^^^^^^
  File "/home/mario/Documentos/Webs/Idea Millonaria/IM/env/lib/python3.13/site-packages/django/contrib/gis/geos/prototypes/threadsafe.py", line 47, in __call__
    return self.cfunc(self.thread_context.handle.ptr, *args)
           ~~~~~~~~~~^^^^^^^^^^^^^^^^^^^^^^^^^^^^^^^^^^^^^^^
  File "/home/mario/Documentos/Webs/Idea Millonaria/IM/env/lib/python3.13/site-packages/django/contrib/gis/geos/prototypes/errcheck.py", line 33, in check_geom
    raise GEOSException(
    ...<2 lines>...
    )
django.contrib.gis.geos.error.GEOSException: Error encountered checking Geometry returned from GEOS C function "GEOSWKBReader_read_r".
"GET /admin/routes/route/ HTTP/1.1" 500 172577
GEOS_ERROR: ParseException: Unknown WKB type 337

GEOS_ERROR: ParseException: Unknown WKB type 337

GEOS_ERROR: ParseException: Unknown WKB type 337

GEOS_ERROR: ParseException: Unknown WKB type 337

Internal Server Error: /admin/routes/route/
Traceback (most recent call last):
  File "/home/mario/Documentos/Webs/Idea Millonaria/IM/env/lib/python3.13/site-packages/django/core/handlers/exception.py", line 55, in inner
    response = get_response(request)
  File "/home/mario/Documentos/Webs/Idea Millonaria/IM/env/lib/python3.13/site-packages/django/core/handlers/base.py", line 197, in _get_response
    response = wrapped_callback(request, *callback_args, **callback_kwargs)
  File "/home/mario/Documentos/Webs/Idea Millonaria/IM/env/lib/python3.13/site-packages/django/contrib/admin/options.py", line 718, in wrapper
    return self.admin_site.admin_view(view)(*args, **kwargs)
           ~~~~~~~~~~~~~~~~~~~~~~~~~~~~~~~~^^^^^^^^^^^^^^^^^
  File "/home/mario/Documentos/Webs/Idea Millonaria/IM/env/lib/python3.13/site-packages/django/utils/decorators.py", line 188, in _view_wrapper
    result = _process_exception(request, e)
  File "/home/mario/Documentos/Webs/Idea Millonaria/IM/env/lib/python3.13/site-packages/django/utils/decorators.py", line 186, in _view_wrapper
    response = view_func(request, *args, **kwargs)
  File "/home/mario/Documentos/Webs/Idea Millonaria/IM/env/lib/python3.13/site-packages/django/views/decorators/cache.py", line 80, in _view_wrapper
    response = view_func(request, *args, **kwargs)
  File "/home/mario/Documentos/Webs/Idea Millonaria/IM/env/lib/python3.13/site-packages/django/contrib/admin/sites.py", line 241, in inner
    return view(request, *args, **kwargs)
  File "/home/mario/Documentos/Webs/Idea Millonaria/IM/env/lib/python3.13/site-packages/django/utils/decorators.py", line 48, in _wrapper
    return bound_method(*args, **kwargs)
  File "/home/mario/Documentos/Webs/Idea Millonaria/IM/env/lib/python3.13/site-packages/django/utils/decorators.py", line 188, in _view_wrapper
    result = _process_exception(request, e)
  File "/home/mario/Documentos/Webs/Idea Millonaria/IM/env/lib/python3.13/site-packages/django/utils/decorators.py", line 186, in _view_wrapper
    response = view_func(request, *args, **kwargs)
  File "/home/mario/Documentos/Webs/Idea Millonaria/IM/env/lib/python3.13/site-packages/django/contrib/admin/options.py", line 2140, in changelist_view
    "selection_note": _("0 of %(cnt)s selected") % {"cnt": len(cl.result_list)},
                                                           ~~~^^^^^^^^^^^^^^^^
  File "/home/mario/Documentos/Webs/Idea Millonaria/IM/env/lib/python3.13/site-packages/django/db/models/query.py", line 382, in __len__
    self._fetch_all()
    ~~~~~~~~~~~~~~~^^
  File "/home/mario/Documentos/Webs/Idea Millonaria/IM/env/lib/python3.13/site-packages/django/db/models/query.py", line 1928, in _fetch_all
    self._result_cache = list(self._iterable_class(self))
                         ~~~~^^^^^^^^^^^^^^^^^^^^^^^^^^^^
  File "/home/mario/Documentos/Webs/Idea Millonaria/IM/env/lib/python3.13/site-packages/django/db/models/query.py", line 123, in __iter__
    for row in compiler.results_iter(results):
               ~~~~~~~~~~~~~~~~~~~~~^^^^^^^^^
  File "/home/mario/Documentos/Webs/Idea Millonaria/IM/env/lib/python3.13/site-packages/django/db/models/sql/compiler.py", line 1512, in apply_converters
    value = converter(value, expression, connection)
  File "/home/mario/Documentos/Webs/Idea Millonaria/IM/env/lib/python3.13/site-packages/django/contrib/gis/db/backends/postgis/operations.py", line 418, in converter
    return None if value is None else GEOSGeometryBase(read(value), geom_class)
                                                       ~~~~^^^^^^^
  File "/home/mario/Documentos/Webs/Idea Millonaria/IM/env/lib/python3.13/site-packages/django/contrib/gis/geos/prototypes/io.py", line 172, in read
    return wkb_reader_read(self.ptr, wkb_s, len(wkb_s))
  File "/home/mario/Documentos/Webs/Idea Millonaria/IM/env/lib/python3.13/site-packages/django/contrib/gis/geos/libgeos.py", line 154, in __call__
    return self.func(*args)
           ~~~~~~~~~^^^^^^^
  File "/home/mario/Documentos/Webs/Idea Millonaria/IM/env/lib/python3.13/site-packages/django/contrib/gis/geos/prototypes/threadsafe.py", line 47, in __call__
    return self.cfunc(self.thread_context.handle.ptr, *args)
           ~~~~~~~~~~^^^^^^^^^^^^^^^^^^^^^^^^^^^^^^^^^^^^^^^
  File "/home/mario/Documentos/Webs/Idea Millonaria/IM/env/lib/python3.13/site-packages/django/contrib/gis/geos/prototypes/errcheck.py", line 33, in check_geom
    raise GEOSException(
    ...<2 lines>...
    )
django.contrib.gis.geos.error.GEOSException: Error encountered checking Geometry returned from GEOS C function "GEOSWKBReader_read_r".
"GET /admin/routes/route/ HTTP/1.1" 500 172213
Internal Server Error: /admin/feed/post/6/change/
Traceback (most recent call last):
  File "/home/mario/Documentos/Webs/Idea Millonaria/IM/env/lib/python3.13/site-packages/django/core/handlers/exception.py", line 55, in inner
    response = get_response(request)
  File "/home/mario/Documentos/Webs/Idea Millonaria/IM/env/lib/python3.13/site-packages/django/core/handlers/base.py", line 197, in _get_response
    response = wrapped_callback(request, *callback_args, **callback_kwargs)
  File "/home/mario/Documentos/Webs/Idea Millonaria/IM/env/lib/python3.13/site-packages/django/contrib/admin/options.py", line 718, in wrapper
    return self.admin_site.admin_view(view)(*args, **kwargs)
           ~~~~~~~~~~~~~~~~~~~~~~~~~~~~~~~~^^^^^^^^^^^^^^^^^
  File "/home/mario/Documentos/Webs/Idea Millonaria/IM/env/lib/python3.13/site-packages/django/utils/decorators.py", line 188, in _view_wrapper
    result = _process_exception(request, e)
  File "/home/mario/Documentos/Webs/Idea Millonaria/IM/env/lib/python3.13/site-packages/django/utils/decorators.py", line 186, in _view_wrapper
    response = view_func(request, *args, **kwargs)
  File "/home/mario/Documentos/Webs/Idea Millonaria/IM/env/lib/python3.13/site-packages/django/views/decorators/cache.py", line 80, in _view_wrapper
    response = view_func(request, *args, **kwargs)
  File "/home/mario/Documentos/Webs/Idea Millonaria/IM/env/lib/python3.13/site-packages/django/contrib/admin/sites.py", line 241, in inner
    return view(request, *args, **kwargs)
  File "/home/mario/Documentos/Webs/Idea Millonaria/IM/env/lib/python3.13/site-packages/django/contrib/admin/options.py", line 1962, in change_view
    return self.changeform_view(request, object_id, form_url, extra_context)
           ~~~~~~~~~~~~~~~~~~~~^^^^^^^^^^^^^^^^^^^^^^^^^^^^^^^^^^^^^^^^^^^^^
  File "/home/mario/Documentos/Webs/Idea Millonaria/IM/env/lib/python3.13/site-packages/django/utils/decorators.py", line 48, in _wrapper
    return bound_method(*args, **kwargs)
  File "/home/mario/Documentos/Webs/Idea Millonaria/IM/env/lib/python3.13/site-packages/django/utils/decorators.py", line 188, in _view_wrapper
    result = _process_exception(request, e)
  File "/home/mario/Documentos/Webs/Idea Millonaria/IM/env/lib/python3.13/site-packages/django/utils/decorators.py", line 186, in _view_wrapper
    response = view_func(request, *args, **kwargs)
  File "/home/mario/Documentos/Webs/Idea Millonaria/IM/env/lib/python3.13/site-packages/django/contrib/admin/options.py", line 1818, in changeform_view
    return self._changeform_view(request, object_id, form_url, extra_context)
           ~~~~~~~~~~~~~~~~~~~~~^^^^^^^^^^^^^^^^^^^^^^^^^^^^^^^^^^^^^^^^^^^^^
  File "/home/mario/Documentos/Webs/Idea Millonaria/IM/env/lib/python3.13/site-packages/django/contrib/admin/options.py", line 1869, in _changeform_view
    self.save_model(request, new_object, form, not add)
    ~~~~~~~~~~~~~~~^^^^^^^^^^^^^^^^^^^^^^^^^^^^^^^^^^^^
  File "/home/mario/Documentos/Webs/Idea Millonaria/IM/env/lib/python3.13/site-packages/django/contrib/admin/options.py", line 1292, in save_model
    obj.save()
    ~~~~~~~~^^
  File "/home/mario/Documentos/Webs/Idea Millonaria/IM/iberomoto/feed/models.py", line 38, in save
    self.compress_video()
    ^^^^^^^^^^^^^^^^^^^
AttributeError: 'Post' object has no attribute 'compress_video'. Did you mean: 'compress_image'?
"POST /admin/feed/post/6/change/ HTTP/1.1" 500 144971
