Internal Server Error: /admin/accounts/customuser/
Traceback (most recent call last):
  File "/home/mario/Documentos/Webs/Idea Millonaria/IM/env/lib/python3.13/site-packages/django/db/backends/utils.py", line 105, in _execute
    return self.cursor.execute(sql, params)
           ~~~~~~~~~~~~~~~~~~~^^^^^^^^^^^^^
psycopg2.errors.UndefinedColumn: no existe la columna accounts_customuser.profile_image
LINE 1: ...muser"."email", "accounts_customuser"."username", "accounts_...
                                                             ^


The above exception was the direct cause of the following exception:

Traceback (most recent call last):
  File "/home/mario/Documentos/Webs/Idea Millonaria/IM/env/lib/python3.13/site-packages/django/core/handlers/exception.py", line 55, in inner
    response = get_response(request)
  File "/home/mario/Documentos/Webs/Idea Millonaria/IM/env/lib/python3.13/site-packages/django/core/handlers/base.py", line 197, in _get_response
    response = wrapped_callback(request, *callback_args, **callback_kwargs)
  File "/home/mario/Documentos/Webs/Idea Millonaria/IM/env/lib/python3.13/site-packages/django/contrib/admin/options.py", line 718, in wrapper
    return self.admin_site.admin_view(view)(*args, **kwargs)
           ~~~~~~~~~~~~~~~~~~~~~~~~~~~~~~~~^^^^^^^^^^^^^^^^^
  File "/home/mario/Documentos/Webs/Idea Millonaria/IM/env/lib/python3.13/site-packages/django/utils/decorators.py", line 188, in _view_wrapper
    result = _process_exception(request, e)
  File "/home/mario/Documentos/Webs/Idea Millonaria/IM/env/lib/python3.13/site-packages/django/utils/decorators.py", line 186, in _view_wrapper
    response = view_func(request, *args, **kwargs)
  File "/home/mario/Documentos/Webs/Idea Millonaria/IM/env/lib/python3.13/site-packages/django/views/decorators/cache.py", line 80, in _view_wrapper
    response = view_func(request, *args, **kwargs)
  File "/home/mario/Documentos/Webs/Idea Millonaria/IM/env/lib/python3.13/site-packages/django/contrib/admin/sites.py", line 229, in inner
    if not self.has_permission(request):
           ~~~~~~~~~~~~~~~~~~~^^^^^^^^^
  File "/home/mario/Documentos/Webs/Idea Millonaria/IM/env/lib/python3.13/site-packages/django/contrib/admin/sites.py", line 202, in has_permission
    return request.user.is_active and request.user.is_staff
           ^^^^^^^^^^^^^^^^^^^^^^
  File "/home/mario/Documentos/Webs/Idea Millonaria/IM/env/lib/python3.13/site-packages/django/utils/functional.py", line 251, in inner
    self._setup()
    ~~~~~~~~~~~^^
  File "/home/mario/Documentos/Webs/Idea Millonaria/IM/env/lib/python3.13/site-packages/django/utils/functional.py", line 404, in _setup
    self._wrapped = self._setupfunc()
                    ~~~~~~~~~~~~~~~^^
  File "/home/mario/Documentos/Webs/Idea Millonaria/IM/env/lib/python3.13/site-packages/django/contrib/auth/middleware.py", line 37, in <lambda>
    request.user = SimpleLazyObject(lambda: get_user(request))
                                            ~~~~~~~~^^^^^^^^^
  File "/home/mario/Documentos/Webs/Idea Millonaria/IM/env/lib/python3.13/site-packages/django/contrib/auth/middleware.py", line 17, in get_user
    request._cached_user = auth.get_user(request)
                           ~~~~~~~~~~~~~^^^^^^^^^
  File "/home/mario/Documentos/Webs/Idea Millonaria/IM/env/lib/python3.13/site-packages/django/contrib/auth/__init__.py", line 216, in get_user
    user = backend.get_user(user_id)
  File "/home/mario/Documentos/Webs/Idea Millonaria/IM/env/lib/python3.13/site-packages/django/contrib/auth/backends.py", line 157, in get_user
    user = UserModel._default_manager.get(pk=user_id)
  File "/home/mario/Documentos/Webs/Idea Millonaria/IM/env/lib/python3.13/site-packages/django/db/models/manager.py", line 87, in manager_method
    return getattr(self.get_queryset(), name)(*args, **kwargs)
           ~~~~~~~~~~~~~~~~~~~~~~~~~~~~~~~~~~^^^^^^^^^^^^^^^^^
  File "/home/mario/Documentos/Webs/Idea Millonaria/IM/env/lib/python3.13/site-packages/django/db/models/query.py", line 645, in get
    num = len(clone)
  File "/home/mario/Documentos/Webs/Idea Millonaria/IM/env/lib/python3.13/site-packages/django/db/models/query.py", line 382, in __len__
    self._fetch_all()
    ~~~~~~~~~~~~~~~^^
  File "/home/mario/Documentos/Webs/Idea Millonaria/IM/env/lib/python3.13/site-packages/django/db/models/query.py", line 1928, in _fetch_all
    self._result_cache = list(self._iterable_class(self))
                         ~~~~^^^^^^^^^^^^^^^^^^^^^^^^^^^^
  File "/home/mario/Documentos/Webs/Idea Millonaria/IM/env/lib/python3.13/site-packages/django/db/models/query.py", line 91, in __iter__
    results = compiler.execute_sql(
        chunked_fetch=self.chunked_fetch, chunk_size=self.chunk_size
    )
  File "/home/mario/Documentos/Webs/Idea Millonaria/IM/env/lib/python3.13/site-packages/django/db/models/sql/compiler.py", line 1574, in execute_sql
    cursor.execute(sql, params)
    ~~~~~~~~~~~~~~^^^^^^^^^^^^^
  File "/home/mario/Documentos/Webs/Idea Millonaria/IM/env/lib/python3.13/site-packages/django/db/backends/utils.py", line 122, in execute
    return super().execute(sql, params)
           ~~~~~~~~~~~~~~~^^^^^^^^^^^^^
  File "/home/mario/Documentos/Webs/Idea Millonaria/IM/env/lib/python3.13/site-packages/django/db/backends/utils.py", line 79, in execute
    return self._execute_with_wrappers(
           ~~~~~~~~~~~~~~~~~~~~~~~~~~~^
        sql, params, many=False, executor=self._execute
        ^^^^^^^^^^^^^^^^^^^^^^^^^^^^^^^^^^^^^^^^^^^^^^^
    )
    ^
  File "/home/mario/Documentos/Webs/Idea Millonaria/IM/env/lib/python3.13/site-packages/django/db/backends/utils.py", line 92, in _execute_with_wrappers
    return executor(sql, params, many, context)
  File "/home/mario/Documentos/Webs/Idea Millonaria/IM/env/lib/python3.13/site-packages/django/db/backends/utils.py", line 100, in _execute
    with self.db.wrap_database_errors:
         ^^^^^^^^^^^^^^^^^^^^^^^^^^^^
  File "/home/mario/Documentos/Webs/Idea Millonaria/IM/env/lib/python3.13/site-packages/django/db/utils.py", line 91, in __exit__
    raise dj_exc_value.with_traceback(traceback) from exc_value
  File "/home/mario/Documentos/Webs/Idea Millonaria/IM/env/lib/python3.13/site-packages/django/db/backends/utils.py", line 105, in _execute
    return self.cursor.execute(sql, params)
           ~~~~~~~~~~~~~~~~~~~^^^^^^^^^^^^^
django.db.utils.ProgrammingError: no existe la columna accounts_customuser.profile_image
LINE 1: ...muser"."email", "accounts_customuser"."username", "accounts_...
                                                             ^

"GET /admin/accounts/customuser/ HTTP/1.1" 500 199322
